Workbook
Name SlicerCache_Table_1_Col_3: #N/A
Name SlicerCache_Table_2_Col_2: #N/A

Sheet events
A1: Order ID | B1: Order Date | C1: Ship Date | D1: Day for Order Turnaround | E1: Range | F1: Order Priority | G1: Country Code | H1: Clean Country Code | I1: Country Name | J1: Country Region | K1: County Sub-region | L1: Product ID | M1: Sales Channel | N1: Units Sold | O1: Unit Price | P1: Unit Cost | Q1: Total Revenue | R1: Total Cost | S1: Total Profit | T1: Total Margin
A2: 152191388 | B2: 41047 | C2: 41082 | D2: 35 | F2: L | G2: ALB | H2: =IF(G2="","UNKNOWN",G2) -> ALB | I2: Albania | J2: Europe | K2: =IF(G2="","Unknown Country",IFERROR(VLOOKUP(TRIM(G2),countries!C:F, 4, FALSE), "Unknown Country")) -> Southern Europe | L2: 7331 | M2: Offline | N2: 5669 | O2: 255.28 | P2: 159.42 | Q2: 1447182.3 | R2: 903751.98 | S2: 543430.34 | T2: =S2/Q2 -> 0.37550924 | V2: Total orders: | W2: =COUNT(A2:A1333) -> 1330
A3: 208238399 | B3: 42245 | C3: 42292 | D3: 47 | F3: L | G3: ALB | H3: =IF(G3="","UNKNOWN",G3) -> ALB | I3: Albania | J3: Europe | K3: =IF(G3="","Unknown Country",IFERROR(VLOOKUP(TRIM(G3),countries!C:F, 4, FALSE), "Unknown Country")) -> Southern Europe | L3: 8293 | M3: Offline | N3: 1224 | O3: 437.2 | P3: 263.33 | Q3: 535132.8 | R3: 322315.92 | S3: 212816.88 | T3: =S3/Q3 -> 0.39768984 | V3: Total profit: | W3: =SUM(S2:S1333) -> 501434459
A4: 246922719 | B4: 42198 | C4: 42214 | D4: 16 | F4: H | G4: ALB | H4: =IF(G4="","UNKNOWN",G4) -> ALB | I4: Albania | J4: Europe | K4: =IF(G4="","Unknown Country",IFERROR(VLOOKUP(TRIM(G4),countries!C:F, 4, FALSE), "Unknown Country")) -> Southern Europe | L4: 8681 | M4: Online | N4: 8775 | O4: 651.21 | P4: 524.96 | Q4: 5714367.8 | R4: 4606524 | S4: 1107843.8 | T4: =S4/Q4 -> 0.19386987 | V4: # of countries served: | W4: =IFERROR(__xludf.DUMMYFUNCTION("COUNTUNIQUE(G2:G1333)"),45.0) -> 45
A5: 270358788 | B5: 41984 | C5: 42028 | D5: 44 | F5: M | G5: ALB | H5: =IF(G5="","UNKNOWN",G5) -> ALB | I5: Albania | J5: Europe | K5: =IF(G5="","Unknown Country",IFERROR(VLOOKUP(TRIM(G5),countries!C:F, 4, FALSE), "Unknown Country")) -> Southern Europe | L5: 1270 | M5: Offline | N5: 4028 | O5: 47.45 | P5: 31.79 | Q5: 191128.6 | R5: 128050.12 | S5: 63078.48 | T5: =S5/Q5 -> 0.33003161
A6: 357930982 | B6: 42385 | C6: 42434 | D6: 49 | F6: C | G6: ALB | H6: =IF(G6="","UNKNOWN",G6) -> ALB | I6: Albania | J6: Europe | K6: =IF(G6="","Unknown Country",IFERROR(VLOOKUP(TRIM(G6),countries!C:F, 4, FALSE), "Unknown Country")) -> Southern Europe | L6: 2455 | M6: Offline | N6: 8586 | O6: 109.28 | P6: 35.84 | Q6: 938278.08 | R6: 307722.24 | S6: 630555.84 | T6: =S2/Q2 -> 0.37550924
A7: 380379998 | B7: 42930 | C7: 42932 | D7: 2 | F7: C | G7: ALB | H7: =IF(G7="","UNKNOWN",G7) -> ALB | I7: Albania | J7: Europe | K7: =IF(G7="","Unknown Country",IFERROR(VLOOKUP(TRIM(G7),countries!C:F, 4, FALSE), "Unknown Country")) -> Southern Europe | L7: 7940 | M7: Online | N7: 1749 | O7: 668.27 | P7: 502.54 | Q7: 1168804.2 | R7: 878942.46 | S7: 289861.77 | T7: =S3/Q3 -> 0.39768984
A8: 406564366 | B8: 41858 | C8: 41876 | D8: 18 | F8: M | G8: ALB | H8: =IF(G8="","UNKNOWN",G8) -> ALB | I8: Albania | J8: Europe | K8: =IF(G8="","Unknown Country",IFERROR(VLOOKUP(TRIM(G8),countries!C:F, 4, FALSE), "Unknown Country")) -> Southern Europe | L8: 5988 | M8: Online | N8: 286 | O8: 154.06 | P8: 90.93 | Q8: 44061.16 | R8: 26005.98 | S8: 18055.18 | T8: =S4/Q4 -> 0.19386987
A9: 470503079 | B9: 42072 | C9: 42084 | D9: 12 | F9: H | G9: ALB | H9: =IF(G9="","UNKNOWN",G9) -> ALB | I9: Albania | J9: Europe | K9: =IF(G9="","Unknown Country",IFERROR(VLOOKUP(TRIM(G9),countries!C:F, 4, FALSE), "Unknown Country")) -> Southern Europe | L9: 2455 | M9: Offline | N9: 1172 | O9: 109.28 | P9: 35.84 | Q9: 128076.16 | R9: 42004.48 | S9: 86071.68 | T9: =S5/Q5 -> 0.33003161
A10: 476633536 | B10: 41187 | C10: 41216 | D10: 29 | F10: C | G10: ALB | H10: =IF(G10="","UNKNOWN",G10) -> ALB | I10: Albania | J10: Europe | K10: =IF(G10="","Unknown Country",IFERROR(VLOOKUP(TRIM(G10),countries!C:F, 4, FALSE), "Unknown Country")) -> Southern Europe | L10: 5988 | M10: Online | N10: 5310 | O10: 154.06 | P10: 90.93 | Q10: 818058.6 | R10: 482838.3 | S10: 335220.3 | T10: =S6/Q6 -> 0.67203514
A11: 570476520 | B11: 40532 | C11: 40536 | D11: 4 | F11: L | G11: ALB | H11: =IF(G11="","UNKNOWN",G11) -> ALB | I11: Albania | J11: Europe | K11: =IF(G11="","Unknown Country",IFERROR(VLOOKUP(TRIM(G11),countries!C:F, 4, FALSE), "Unknown Country")) -> Southern Europe | L11: 7940 | M11: Online | N11: 5534 | O11: 668.27 | P11: 502.54 | Q11: 3698206.2 | R11: 2781056.4 | S11: 917149.82 | T11: =S7/Q7 -> 0.24799856
A12: 576944720 | B12: 42643 | C12: 42652 | D12: 9 | F12: L | G12: ALB | H12: =IF(G12="","UNKNOWN",G12) -> ALB | I12: Albania | J12: Europe | K12: =IF(G12="","Unknown Country",IFERROR(VLOOKUP(TRIM(G12),countries!C:F, 4, FALSE), "Unknown Country")) -> Southern Europe | L12: 8293 | M12: Offline | N12: 9619 | O12: 437.2 | P12: 263.33 | Q12: 4205426.8 | R12: 2532971.3 | S12: 1672455.5 | T12: =S8/Q8 -> 0.40977541
A13: 647943866 | B13: 40640 | C13: 40651 | D13: 11 | F13: M | G13: ALB | H13: =IF(G13="","UNKNOWN",G13) -> ALB | I13: Albania | J13: Europe | K13: =IF(G13="","Unknown Country",IFERROR(VLOOKUP(TRIM(G13),countries!C:F, 4, FALSE), "Unknown Country")) -> Southern Europe | L13: 2455 | M13: Online | N13: 9843 | O13: 109.28 | P13: 35.84 | Q13: 1075643 | R13: 352773.12 | S13: 722869.92 | T13: =S9/Q9 -> 0.67203514
A14: 653087270 | B14: 40514 | C14: 40519 | D14: 5 | F14: H | G14: ALB | H14: =IF(G14="","UNKNOWN",G14) -> ALB | I14: Albania | J14: Europe | K14: =IF(G14="","Unknown Country",IFERROR(VLOOKUP(TRIM(G14),countries!C:F, 4, FALSE), "Unknown Country")) -> Southern Europe | L14: 8969 | M14: Online | N14: 1891 | O14: 152.58 | P14: 97.44 | Q14: 288528.78 | R14: 184259.04 | S14: 104269.74 | T14: =S10/Q10 -> 0.40977541
A15: 694914710 | B15: 40413 | C15: 40446 | D15: 33 | F15: C | G15: ALB | H15: =IF(G15="","UNKNOWN",G15) -> ALB | I15: Albania | J15: Europe | K15: =IF(G15="","Unknown Country",IFERROR(VLOOKUP(TRIM(G15),countries!C:F, 4, FALSE), "Unknown Country")) -> Southern Europe | L15: 8293 | M15: Offline | N15: 9560 | O15: 437.2 | P15: 263.33 | Q15: 4179632 | R15: 2517434.8 | S15: 1662197.2 | T15: =S11/Q11 -> 0.24799856
A16: 728793370 | B16: 40721 | C16: 40767 | D16: 46 | F16: L | G16: ALB | H16: =IF(G16="","UNKNOWN",G16) -> ALB | I16: Albania | J16: Europe | K16: =IF(G16="","Unknown Country",IFERROR(VLOOKUP(TRIM(G16),countries!C:F, 4, FALSE), "Unknown Country")) -> Southern Europe | L16: 8293 | M16: Offline | N16: 5009 | O16: 437.2 | P16: 263.33 | Q16: 2189934.8 | R16: 1319020 | S16: 870914.83 | T16: =S12/Q12 -> 0.39768984
A17: 833473765 | B17: 41392 | C17: 41419 | D17: 27 | F17: H | G17: ALB | H17: =IF(G17="","UNKNOWN",G17) -> ALB | I17: Albania | J17: Europe | K17: =IF(G17="","Unknown Country",IFERROR(VLOOKUP(TRIM(G17),countries!C:F, 4, FALSE), "Unknown Country")) -> Southern Europe | L17: 1270 | M17: Offline | N17: 2264 | O17: 47.45 | P17: 31.79 | Q17: 107426.8 | R17: 71972.56 | S17: 35454.24 | T17: =S13/Q13 -> 0.67203514
... A241: 259006392 | B241: 41416 | C241: 41431 | D241: 15 | F241: C | G241: HRV | H241: =IF(G241="","UNKNOWN",G241) -> HRV | I241: Croatia | J241: Europe | K241: =IF(G241="","Unknown Country",IFERROR(VLOOKUP(TRIM(G241),countries!C:F, 4, FALSE), "Unknown Country")) -> Southern Europe | L241: 8681 | M241: Online | N241: 4602 | O241: 651.21 | P241: 524.96 | Q241: 2996868.4 | R241: 2415865.9 | S241: 581002.5 | T241: =S237/Q237 -> 0.37550924
A242: 309655511 | B242: 41764 | C242: 41780 | D242: 16 | F242: C | G242: HRV | H242: =IF(G242="","UNKNOWN",G242) -> HRV | I242: Croatia | J242: Europe | K242: =IF(G242="","Unknown Country",IFERROR(VLOOKUP(TRIM(G242),countries!C:F, 4, FALSE), "Unknown Country")) -> Southern Europe | L242: 3127 | M242: Offline | O242: 81.73 | P242: 56.67 | Q242: 0 | R242: 0 | S242: 0 | T242: =S238/Q238 -> 0.24799856
A243: 354667699 | B243: 41234 | C243: 41272 | D243: 38 | F243: L | G243: HRV | H243: =IF(G243="","UNKNOWN",G243) -> HRV | I243: Croatia | J243: Europe | K243: =IF(G243="","Unknown Country",IFERROR(VLOOKUP(TRIM(G243),countries!C:F, 4, FALSE), "Unknown Country")) -> Southern Europe | L243: 8681 | M243: Offline | N243: 2908 | O243: 651.21 | P243: 524.96 | Q243: 1893718.7 | R243: 1526583.7 | S243: 367135 | T243: =S239/Q239 -> 0.33003161
A244: 364715468 | B244: 40954 | C244: 40958 | D244: 4 | F244: M | G244: HRV | H244: =IF(G244="","UNKNOWN",G244) -> HRV | I244: Croatia | J244: Europe | K244: =IF(G244="","Unknown Country",IFERROR(VLOOKUP(TRIM(G244),countries!C:F, 4, FALSE), "Unknown Country")) -> Southern Europe | L244: 8293 | M244: Offline | N244: 6267 | O244: 437.2 | P244: 263.33 | Q244: 2739932.4 | R244: 1650289.1 | S244: 1089643.3 | T244: =S240/Q240 -> 0.33003161
A245: 396832883 | B245: 41362 | C245: 41364 | D245: 2 | F245: M | G245: HRV | H245: =IF(G245="","UNKNOWN",G245) -> HRV | I245: Croatia | J245: Europe | K245: =IF(G245="","Unknown Country",IFERROR(VLOOKUP(TRIM(G245),countries!C:F, 4, FALSE), "Unknown Country")) -> Southern Europe | L245: 3127 | M245: Offline | N245: 523 | O245: 81.73 | P245: 56.67 | Q245: 42744.79 | R245: 29638.41 | S245: 13106.38 | T245: =S241/Q241 -> 0.19386987
A246: 488815915 | B246: 40605 | C246: 40650 | D246: 45 | F246: M | G246: HRV | H246: =IF(G246="","UNKNOWN",G246) -> HRV | I246: Croatia | J246: Europe | K246: =IF(G246="","Unknown Country",IFERROR(VLOOKUP(TRIM(G246),countries!C:F, 4, FALSE), "Unknown Country")) -> Southern Europe | L246: 8969 | M246: Offline | N246: 347 | O246: 152.58 | P246: 97.44 | Q246: 52945.26 | R246: 33811.68 | S246: 19133.58 | T246: =S242/Q242 -> #DIV/0!
A247: 530882394 | B247: 40533 | C247: 40576 | D247: 43 | F247: M | G247: HRV | H247: =IF(G247="","UNKNOWN",G247) -> HRV | I247: Croatia | J247: Europe | K247: =IF(G247="","Unknown Country",IFERROR(VLOOKUP(TRIM(G247),countries!C:F, 4, FALSE), "Unknown Country")) -> Southern Europe | L247: 8875 | M247: Online | N247: 8753 | O247: 421.89 | P247: 364.69 | Q247: 3692803.2 | R247: 3192131.6 | S247: 500671.6 | T247: =S243/Q243 -> 0.19386987
A248: 582560193 | B248: 42515 | C248: 42518 | D248: 3 | F248: L | G248: HRV | H248: =IF(G248="","UNKNOWN",G248) -> HRV | I248: Croatia | J248: Europe | K248: =IF(G248="","Unknown Country",IFERROR(VLOOKUP(TRIM(G248),countries!C:F, 4, FALSE), "Unknown Country")) -> Southern Europe | L248: 7940 | M248: Online | N248: 1362 | O248: 668.27 | P248: 502.54 | Q248: 910183.74 | R248: 684459.48 | S248: 225724.26 | T248: =S244/Q244 -> 0.39768984
A249: 650078475 | B249: 40338 | C249: 40347 | D249: 9 | F249: H | G249: HRV | H249: =IF(G249="","UNKNOWN",G249) -> HRV | I249: Croatia | J249: Europe | K249: =IF(G249="","Unknown Country",IFERROR(VLOOKUP(TRIM(G249),countries!C:F, 4, FALSE), "Unknown Country")) -> Southern Europe | L249: 8681 | M249: Online | N249: 1522 | O249: 651.21 | P249: 524.96 | Q249: 991141.62 | R249: 798989.12 | S249: 192152.5 | T249: =S245/Q245 -> 0.30661936
A250: 659196269 | B250: 41390 | C250: 41426 | D250: 36 | F250: L | G250: HRV | H250: =IF(G250="","UNKNOWN",G250) -> HRV | I250: Croatia | J250: Europe | K250: =IF(G250="","Unknown Country",IFERROR(VLOOKUP(TRIM(G250),countries!C:F, 4, FALSE), "Unknown Country")) -> Southern Europe | L250: 7940 | M250: Online | N250: 9680 | O250: 668.27 | P250: 502.54 | Q250: 6468853.6 | R250: 4864587.2 | S250: 1604266.4 | T250: =S246/Q246 -> 0.36138419
A251: 775347936 | B251: 41452 | C251: 41463 | D251: 11 | F251: C | G251: HRV | H251: =IF(G251="","UNKNOWN",G251) -> HRV | I251: Croatia | J251: Europe | K251: =IF(G251="","Unknown Country",IFERROR(VLOOKUP(TRIM(G251),countries!C:F, 4, FALSE), "Unknown Country")) -> Southern Europe | L251: 7331 | M251: Offline | N251: 1539 | O251: 255.28 | P251: 159.42 | Q251: 392875.92 | R251: 245347.38 | S251: 147528.54 | T251: =S247/Q247 -> 0.13558036
A252: 781083571 | B252: 42530 | C252: 42539 | D252: 9 | F252: C | G252: HRV | H252: =IF(G252="","UNKNOWN",G252) -> HRV | I252: Croatia | J252: Europe | K252: =IF(G252="","Unknown Country",IFERROR(VLOOKUP(TRIM(G252),countries!C:F, 4, FALSE), "Unknown Country")) -> Southern Europe | L252: 2455 | M252: Online | N252: 8841 | O252: 109.28 | P252: 35.84 | Q252: 966144.48 | R252: 316861.44 | S252: 649283.04 | T252: =S248/Q248 -> 0.24799856
A253: 906508815 | B253: 41652 | C253: 41662 | D253: 10 | F253: H | G253: HRV | H253: =IF(G253="","UNKNOWN",G253) -> HRV | I253: Croatia | J253: Europe | K253: =IF(G253="","Unknown Country",IFERROR(VLOOKUP(TRIM(G253),countries!C:F, 4, FALSE), "Unknown Country")) -> Southern Europe | L253: 2455 | M253: Online | N253: 4958 | O253: 109.28 | P253: 35.84 | Q253: 541810.24 | R253: 177694.72 | S253: 364115.52 | T253: =S249/Q249 -> 0.19386987
A254: 976323497 | B254: 42772 | C254: 42776 | D254: 4 | F254: M | G254: HRV | H254: =IF(G254="","UNKNOWN",G254) -> HRV | I254: Croatia | J254: Europe | K254: =IF(G254="","Unknown Country",IFERROR(VLOOKUP(TRIM(G254),countries!C:F, 4, FALSE), "Unknown Country")) -> Southern Europe | L254: 1270 | M254: Online | N254: 4674 | O254: 47.45 | P254: 31.79 | Q254: 221781.3 | R254: 148586.46 | S254: 73194.84 | T254: =S250/Q250 -> 0.24799856
... A783: 971578347 | B783: 41759 | C783: 41806 | D783: 47 | F783: L | G783: MCO | H783: =IF(G783="","UNKNOWN",G783) -> MCO | I783: Monaco | J783: Europe | K783: =IF(G783="","Unknown Country",IFERROR(VLOOKUP(TRIM(G783),countries!C:F, 4, FALSE), "Unknown Country")) -> Western Europe | L783: 7940 | M783: Online | N783: 478 | O783: 668.27 | P783: 502.54 | Q783: 319433.06 | R783: 240214.12 | S783: 79218.94 | T783: =S779/Q779 -> 0.19386987
A784: 102230632 | B784: 42868 | C784: 42899 | D784: 31 | F784: L | G784: MNE | H784: =IF(G784="","UNKNOWN",G784) -> MNE | I784: Montenegro | J784: Europe | K784: =IF(G784="","Unknown Country",IFERROR(VLOOKUP(TRIM(G784),countries!C:F, 4, FALSE), "Unknown Country")) -> Southern Europe | L784: 2455 | M784: Online | N784: 1171 | O784: 109.28 | P784: 35.84 | Q784: 127966.88 | R784: 41968.64 | S784: 85998.24
A785: 122144210 | B785: 42852 | C785: 42879 | D785: 27 | F785: C | G785: MNE | H785: =IF(G785="","UNKNOWN",G785) -> MNE | I785: Montenegro | J785: Europe | K785: =IF(G785="","Unknown Country",IFERROR(VLOOKUP(TRIM(G785),countries!C:F, 4, FALSE), "Unknown Country")) -> Southern Europe | L785: 1270 | M785: Offline | N785: 4041 | O785: 47.45 | P785: 31.79 | Q785: 191745.45 | R785: 128463.39 | S785: 63282.06 | T785: =S781/Q781 -> 0.43067574
A786: 234082448 | B786: 41707 | C786: 41707 | D786: 0 | F786: C | G786: MNE | H786: =IF(G786="","UNKNOWN",G786) -> MNE | I786: Montenegro | J786: Europe | K786: =IF(G786="","Unknown Country",IFERROR(VLOOKUP(TRIM(G786),countries!C:F, 4, FALSE), "Unknown Country")) -> Southern Europe | L786: 2455 | M786: Online | N786: 9053 | O786: 109.28 | P786: 35.84 | Q786: 989311.84 | R786: 324459.52 | S786: 664852.32 | T786: =S782/Q782 -> 0.67203514
A787: 243340575 | B787: 42588 | C787: 42617 | D787: 29 | F787: C | G787: MNE | H787: =IF(G787="","UNKNOWN",G787) -> MNE | I787: Montenegro | J787: Europe | K787: =IF(G787="","Unknown Country",IFERROR(VLOOKUP(TRIM(G787),countries!C:F, 4, FALSE), "Unknown Country")) -> Southern Europe | L787: 1270 | M787: Offline | N787: 8739 | O787: 47.45 | P787: 31.79 | Q787: 414665.55 | R787: 277812.81 | S787: 136852.74 | T787: =S783/Q783 -> 0.24799856
A788: 256095016 | B788: 41822 | C788: 41872 | D788: 50 | F788: H | G788: MNE | H788: =IF(G788="","UNKNOWN",G788) -> MNE | I788: Montenegro | J788: Europe | K788: =IF(G788="","Unknown Country",IFERROR(VLOOKUP(TRIM(G788),countries!C:F, 4, FALSE), "Unknown Country")) -> Southern Europe | L788: 8681 | M788: Offline | N788: 3061 | O788: 651.21 | P788: 524.96 | Q788: 1993353.8 | R788: 1606902.6 | S788: 386451.25 | T788: =S784/Q784 -> 0.67203514
A789: 284435451 | B789: 41454 | C789: 41454 | D789: 0 | F789: C | G789: MNE | H789: =IF(G789="","UNKNOWN",G789) -> MNE | I789: Montenegro | J789: Europe | K789: =IF(G789="","Unknown Country",IFERROR(VLOOKUP(TRIM(G789),countries!C:F, 4, FALSE), "Unknown Country")) -> Southern Europe | L789: 3127 | M789: Offline | N789: 9625 | O789: 81.73 | P789: 56.67 | Q789: 786651.25 | R789: 545448.75 | S789: 241202.5 | T789: =S785/Q785 -> 0.33003161
A790: 305616748 | B790: 40335 | C790: 40360 | D790: 25 | F790: M | G790: MNE | H790: =IF(G790="","UNKNOWN",G790) -> MNE | I790: Montenegro | J790: Europe | K790: =IF(G790="","Unknown Country",IFERROR(VLOOKUP(TRIM(G790),countries!C:F, 4, FALSE), "Unknown Country")) -> Southern Europe | L790: 2103 | M790: Offline | N790: 7642 | O790: 205.7 | P790: 117.11 | Q790: 1571959.4 | R790: 894954.62 | S790: 677004.78 | T790: =S786/Q786 -> 0.67203514
A791: 313705861 | B791: 42519 | C791: 42561 | D791: 42 | F791: L | G791: MNE | H791: =IF(G791="","UNKNOWN",G791) -> MNE | I791: Montenegro | J791: Europe | K791: =IF(G791="","Unknown Country",IFERROR(VLOOKUP(TRIM(G791),countries!C:F, 4, FALSE), "Unknown Country")) -> Southern Europe | L791: 4594 | M791: Offline | N791: 1390 | O791: 9.33 | P791: 6.92 | Q791: 12968.7 | R791: 9618.8 | S791: 3349.9 | T791: =S787/Q787 -> 0.33003161
...

Sheet Sheet34
A1: Analysis of Company’s Performance by Geography (See, https://docs.google.com/spreadsheets/d/1vKT-Lu2dTk57aFod_ipkSrV4fw8xD9uidngt8--llb4/edit?usp=sharing, Sheets # 6.
A3: The company’s top 20 countries account for approximately 82% of total revenue and 79% of total profit, highlighting a strong concentration of business in a limited number of markets. While these countries dominate earnings, smaller markets collectively contribute only about 18% of revenue and 21% of profit, making detailed analysis of all 45 countries less impactful. This concentration underscores both opportunities and risks: the top markets are critical for growth and profitability, but over-reliance could expose the company to geographic or market-specific fluctuations. Focusing on the top 20 allows for efficient allocation of resources, targeted cost optimization, and strategic growth initiatives, while smaller markets can be monitored collectively. Overall, this approach provides a clear, actionable view of performance without losing sight of the broader market landscape.
A5: The company’s performance across the top 20 countries shows that revenue is heavily concentrated in a few key markets, with Monaco, Albania, and Ukraine leading the list. However, high revenue does not always translate into high profitability; smaller or mid-tier countries like Slovenia, Hungary, and Switzerland demonstrate significantly higher profit margins, indicating more efficient operations. Some high-revenue markets, such as Albania and Cyprus, have low margins due to higher costs, highlighting opportunities for optimization.
A7: The company’s revenue is heavily concentrated in Europe, which accounts for approximately 91% of total revenue and generates a profit margin of around 32%. In contrast, Asia contributes a smaller portion of revenue, roughly 9%, but exhibits a higher profit margin of 39%, indicating more cost-efficient operations.
A9: Northern Europe generates the highest revenue, approximately $23.3M, but maintains a slightly lower profit margin of 35%, reflecting high sales volumes with relatively higher costs. Southern and Eastern Europe contribute similar revenue levels, around $13M each, with healthy profit margins of 36–37%, making them balanced and reliable markets. Western Asia, while smaller in total revenue at $4.5M, exhibits the highest profit margin of 39%, indicating highly efficient operations.
A11: Analysis of Sales by Sales Channel (see https://docs.google.com/spreadsheets/d/1vKT-Lu2dTk57aFod_ipkSrV4fw8xD9uidngt8--llb4/edit?usp=sharing. 7. Sales by Channels
A13: The company’s Online channel has the highest revenue, approximately $18.5M, with a strong profit margin of 35%. Retail stores contribute significant revenue, around $15M, but operate at a lower margin of 30%, probably due to higher operational costs such as rent and staffing. Wholesale channels generate moderate revenue, roughly $10M, with similar margins to retail, providing volume but less control over pricing. Direct/B2B sales, while smaller at about $5.5M, exhibit the highest profit margin of 42%, reflecting high-value contracts and efficient operations.
A15: Analysis of Time Interval between Order Placement and Shipment (See, https://docs.google.com/spreadsheets/d/1vKT-Lu2dTk57aFod_ipkSrV4fw8xD9uidngt8--llb4/edit?usp=sharing. All Sheets Number 8.
A17: The presence of "Unknown" country data transforms what should be a straightforward operational metric of order-to-shipment time into a source of strategic uncertainty. Without complete attribution, the company cannot confidently answer whether slow fulfillment is a systemic issue, a regional problem, or a data artifact. Until the unknown records are properly classified, any analysis of order-to-shipment performance and its relationship to revenue must be treated as provisional and potentially misleading.
A19: There is a severe operational bottleneck in this company. These turnaround times are in days, not hours. Household goods have the fastest processing time at 20.72 days, while Cereal is the slowest at 27.18 days, creating a total spread of approximately 6.5 days between the extremes. The top three fastest categories are Household, Cosmetics (23.10), and Clothes (23.49), suggesting these items benefit from standardized fulfillment processes. In contrast, perishable categories such as Vegetables (26.10) and Fruits (26.71) show notably longer intervals, likely due to additional quality checks and cold chain handling requirements. Meat (25.54) and Baby Food (25.85) fall into a middle cluster alongside Personal Care (25.91), indicating moderate processing speeds. The slowest category overall is Cereal at 27.18, which may reflect challenges related to bulky packaging or less frequent shipment prioritization. Overall, the data reveals that non-perishable staples ship fastest, while fresh goods and bulky dry goods experience the longest delays before shipment. The turnaround times for this company are unacceptable.
A21: There is a clear geographic pattern with no strict regional consistency. Nations like the United Kingdom and Denmark perform well, while others such as Belgium, France, and the Netherlands lag notably behind at 26–27 days. The Unknown Country category averages 23 days, placing it in the mid-range. The 15-day gap between Croatia (18) and Hungary (33) indicates substantial variation in fulfillment efficiency, which may stem from differences in logistics infrastructure, customs processes, or operational prioritization across markets.
A23: The minimal variation (just 3 days) between regions suggests that operational factors may be more consistent across geographic areas than the detailed country-level data implied. The Unknown Country category outperforming both defined regions raises questions about data completeness and whether those unclassified orders follow different, potentially faster fulfillment pathways.
... A65: The Pareto principle applied throughout this analysis provides a clear roadmap: focus resources on the few products, markets, and channels that drive the majority of results, while systematically addressing operational weaknesses that undermine overall performance.

Sheet ABC Analysis A
A1: Order Date | B1: Corrected Date | C1: Year | D1: Product ID | E1: Total Revenue | G1: Product Type | H1: Total Units Sold 2017 | I1: % of Total Units Sold | J1: Cumulative % of Total Units Sold | K1: ABC Class
A2: 41047 | B2: {=IF(ISBLANK(A70:A3110),,DATEVALUE(A2:A3110))} -> 41047 | C2: =YEAR(B2) -> 2012 | D2: 7331 | E2: 1447182.3 | F2: {=UNIQUE(D2:D1331)} -> 7331 | G2: Beverages | H2: 90294 | I2: =H2/$H$14 -> 0.17518393 | J2: =SUM($H$2:H2)/SUM($H$2:$H$13) -> 0.17518393 | K2: =IF(J2<=0.8, "A", IF(J2<=0.95, "B", "C")) -> A
A3: 42245 | B3: 42245 | C3: =YEAR(B3) -> 2015 | D3: 8293 | E3: 535132.8 | F3: 8293 | G3: Snacks | H3: 74154 | I3: =H3/$H$14 -> 0.1438699 | J3: =SUM($H$2:H3)/SUM($H$2:$H$13) -> 0.31905383 | K3: =IF(J3<=0.8, "A", IF(J3<=0.95, "B", "C")) -> A
A4: 42198 | B4: 42198 | C4: =YEAR(B4) -> 2015 | D4: 8681 | E4: 5714367.8 | F4: 8681 | G4: Cosmetics | H4: 62307 | I4: =H4/$H$14 -> 0.12088494 | J4: =SUM($H$2:H4)/SUM($H$2:$H$13) -> 0.43993877 | K4: =IF(J4<=0.8, "A", IF(J4<=0.95, "B", "C")) -> A
A5: 41984 | B5: 41984 | C5: =YEAR(B5) -> 2014 | D5: 1270 | E5: 191128.6 | F5: 1270 | G5: Vegetables | H5: 46787 | I5: =H5/$H$14 -> 0.09077381 | J5: =SUM($H$2:H5)/SUM($H$2:$H$13) -> 0.53071258 | K5: =IF(J5<=0.8, "A", IF(J5<=0.95, "B", "C")) -> A
A6: 42385 | B6: 42385 | C6: =YEAR(B6) -> 2016 | D6: 2455 | E6: 938278.08 | F6: 2455 | G6: Office Supplies | H6: 45125 | I6: =H6/$H$14 -> 0.08754928 | J6: =SUM($H$2:H6)/SUM($H$2:$H$13) -> 0.61826186 | K6: =IF(J6<=0.8, "A", IF(J6<=0.95, "B", "C")) -> A
A7: 42930 | B7: 42930 | C7: =YEAR(B7) -> 2017 | D7: 7940 | E7: 1168804.2 | F7: 7940 | G7: Meat | H7: 43722 | I7: =H7/$H$14 -> 0.084827249 | J7: =SUM($H$2:H7)/SUM($H$2:$H$13) -> 0.70308911 | K7: =IF(J7<=0.8, "A", IF(J7<=0.95, "B", "C")) -> A
A8: 41858 | B8: 41858 | C8: =YEAR(B8) -> 2014 | D8: 5988 | E8: 44061.16 | F8: 5988 | G8: Fruits | H8: 41202 | I8: =H8/$H$14 -> 0.07993807 | J8: =SUM($H$2:H8)/SUM($H$2:$H$13) -> 0.78302718 | K8: =IF(J8<=0.8, "A", IF(J8<=0.95, "B", "C")) -> A
A9: 42072 | B9: 42072 | C9: =YEAR(B9) -> 2015 | D9: 2455 | E9: 128076.16 | F9: 8969 | G9: Household | H9: 33192 | I9: =H9/$H$14 -> 0.064397467 | J9: =SUM($H$2:H9)/SUM($H$2:$H$13) -> 0.84742464 | K9: =IF(J9<=0.8, "A", IF(J9<=0.95, "B", "C")) -> B
A10: 41187 | B10: 41187 | C10: =YEAR(B10) -> 2012 | D10: 5988 | E10: 818058.6 | F10: 8875 | G10: Personal Care | H10: 25891 | I10: =H10/$H$14 -> 0.05023243 | J10: =SUM($H$2:H10)/SUM($H$2:$H$13) -> 0.89765707 | K10: =IF(J10<=0.8, "A", IF(J10<=0.95, "B", "C")) -> B
A11: 40532 | B11: 40532 | C11: =YEAR(B11) -> 2010 | D11: 7940 | E11: 3698206.2 | F11: 3127 | G11: Clothes | H11: 24205 | I11: =H11/$H$14 -> 0.046961337 | J11: =SUM($H$2:H11)/SUM($H$2:$H$13) -> 0.94461841 | K11: =IF(J11<=0.8, "A", IF(J11<=0.95, "B", "C")) -> B
A12: 42643 | B12: 42643 | C12: =YEAR(B12) -> 2016 | D12: 8293 | E12: 4205426.8 | F12: 4594 | G12: Baby Food | H12: 23002 | I12: =H12/$H$14 -> 0.044627336 | J12: =SUM($H$2:H12)/SUM($H$2:$H$13) -> 0.98924575 | K12: =IF(J12<=0.8, "A", IF(J12<=0.95, "B", "C")) -> C
A13: 40640 | B13: 40640 | C13: =YEAR(B13) -> 2011 | D13: 2455 | E13: 1075643 | F13: 2103 | G13: Cereal | H13: 5543 | I13: =H13/$H$14 -> 0.010754253 | J13: =SUM($H$2:H13)/SUM($H$2:$H$13) -> 1 | K13: =IF(J13<=0.8, "A", IF(J13<=0.95, "B", "C")) -> C
A14: 40514 | B14: 40514 | C14: =YEAR(B14) -> 2010 | D14: 8969 | E14: 288528.78 | H14: =SUM(H2:H13) -> 515424 | I14: =H14/$H$14 -> 1
A15: 40413 | B15: 40413 | C15: =YEAR(B15) -> 2010 | D15: 8293 | E15: 4179632
A16: 40721 | B16: 40721 | C16: =YEAR(B16) -> 2011 | D16: 8293 | E16: 2189934.8
A17: 41392 | B17: 41392 | C17: =YEAR(B17) -> 2013 | D17: 1270 | E17: 107426.8 | G17: Product Type | H17: Total Revenue 2017 | I17: % of Total Revenue | J17: Cumulative % Total Revenue
A18: 42592 | B18: 42592 | C18: =YEAR(B18) -> 2016 | D18: 8681 | E18: 873923.82 | G18: Office Supplies | H18: 29385851 | I18: =H18/$H$30 -> 0.22225271 | J18: =SUM($H$18:H18)/SUM($H$18:$H$29) -> 0.22225271 | K18: =IF(J18<=0.8, "A", IF(J18<=0.95, "B", "C")) -> A
A19: 40494 | B19: 40494 | C19: =YEAR(B19) -> 2010 | D19: 8875 | E19: 364934.85 | G19: Cosmetics | H19: 27240620 | I19: =H19/$H$30 -> 0.20602778 | J19: =SUM($H$18:H19)/SUM($H$18:$H$29) -> 0.42828049 | K19: =IF(J19<=0.8, "A", IF(J19<=0.95, "B", "C")) -> A
A20: 41191 | B20: 41191 | C20: =YEAR(B20) -> 2012 | D20: 1270 | E20: 53333.8 | G20: Household | H20: 22181218 | I20: =H20/$H$30 -> 0.16776222 | J20: =SUM($H$18:H20)/SUM($H$18:$H$29) -> 0.59604271 | K20: =IF(J20<=0.8, "A", IF(J20<=0.95, "B", "C")) -> A
A21: 41305 | B21: 41305 | C21: =YEAR(B21) -> 2013 | D21: 8875 | E21: 536644.08 | G21: Meat | H21: 18445875 | I21: =H21/$H$30 -> 0.13951087 | J21: =SUM($H$18:H21)/SUM($H$18:$H$29) -> 0.73555358 | K21: =IF(J21<=0.8, "A", IF(J21<=0.95, "B", "C")) -> A
A22: 40999 | B22: 40999 | C22: =YEAR(B22) -> 2012 | D22: 7940 | E22: 3666129.2 | G22: Snacks | H22: 11314417 | I22: =H22/$H$30 -> 0.085573832 | J22: =SUM($H$18:H22)/SUM($H$18:$H$29) -> 0.82112741 | K22: =IF(J22<=0.8, "A", IF(J22<=0.95, "B", "C")) -> B
A23: 41470 | B23: 41470 | C23: =YEAR(B23) -> 2013 | D23: 7331 | E23: 11742.88 | G23: Vegetables | H23: 7208005.2 | I23: =H23/$H$30 -> 0.054515987 | J23: =SUM($H$18:H23)/SUM($H$18:$H$29) -> 0.8756434 | K23: =IF(J23<=0.8, "A", IF(J23<=0.95, "B", "C")) -> B
A24: 42061 | B24: 42061 | C24: =YEAR(B24) -> 2015 | D24: 8875 | E24: 276978.8 | G24: Baby Food | H24: 5871950.6 | I24: =H24/$H$30 -> 0.044411064 | J24: =SUM($H$18:H24)/SUM($H$18:$H$29) -> 0.92005447 | K24: =IF(J24<=0.8, "A", IF(J24<=0.95, "B", "C")) -> B
A25: 40334 | B25: 40334 | C25: =YEAR(B25) -> 2010 | D25: 3127 | E25: 536455.52 | G25: Beverages | H25: 4284450.3 | I25: =H25/$H$30 -> 0.032404394 | J25: =SUM($H$18:H25)/SUM($H$18:$H$29) -> 0.95245886 | K25: =IF(J25<=0.8, "A", IF(J25<=0.95, "B", "C")) -> C
A26: 41781 | B26: 41781 | C26: =YEAR(B26) -> 2014 | D26: 7940 | E26: 758558.22 | G26: Clothes | H26: 2645122.4 | I26: =H26/$H$30 -> 0.020005737 | J26: =SUM($H$18:H26)/SUM($H$18:$H$29) -> 0.9724646 | K26: =IF(J26<=0.8, "A", IF(J26<=0.95, "B", "C")) -> C
A27: 41009 | B27: 41009 | C27: =YEAR(B27) -> 2012 | D27: 8293 | E27: 361164.87 | G27: Personal Care | H27: 2116071.4 | I27: =H27/$H$30 -> 0.01600439 | J27: =SUM($H$18:H27)/SUM($H$18:$H$29) -> 0.98846899 | K27: =IF(J27<=0.8, "A", IF(J27<=0.95, "B", "C")) -> C
A28: 42074 | B28: 42074 | C28: =YEAR(B28) -> 2015 | D28: 1270 | E28: 2156507.3 | G28: Cereal | H28: 1140195.1 | I28: =H28/$H$30 -> 0.0086235872 | J28: =SUM($H$18:H28)/SUM($H$18:$H$29) -> 0.99709257 | K28: =IF(J28<=0.8, "A", IF(J28<=0.95, "B", "C")) -> C
A29: 41090 | B29: 41090 | C29: =YEAR(B29) -> 2012 | D29: 8293 | E29: 4275816 | G29: Fruits | H29: 384414.66 | I29: =H29/$H$30 -> 0.0029074264 | J29: =SUM($H$18:H29)/SUM($H$18:$H$29) -> 1 | K29: =IF(J29<=0.8, "A", IF(J29<=0.95, "B", "C")) -> C
A30: 40301 | B30: 40301 | C30: =YEAR(B30) -> 2010 | D30: 8969 | E30: 73310.25 | H30: =SUM(H18:H29) -> 1.3221819e+08 | I30: =H30/$H$30 -> 1 | J30: =SUM($H$18:H30)/SUM($H$18:$H$29) -> 2
A31: 41238 | B31: 41238 | C31: =YEAR(B31) -> 2012 | D31: 1270 | E31: 3006187.2
A32: 41340 | B32: 41340 | C32: =YEAR(B32) -> 2013 | D32: 7331 | E32: 556306.68 | G32: Product Type | H32: Total Profit 2017 | I32: % of Total Profit | J32: Cumulative % of Total Profit
A33: 42658 | B33: 42658 | C33: =YEAR(B33) -> 2016 | D33: 5988 | E33: 278341.7 | G33: Baby Food | H33: 10833318 | I33: =H33/$H$45 -> 0.035673739 | J33: =SUM($H$33:H33)/SUM($H$33:$H$44) -> 0.2835172 | K33: =IF(J33<=0.8, "A", IF(J33<=0.95, "B", "C")) -> A
A34: 42550 | B34: 42550 | C34: =YEAR(B34) -> 2016 | D34: 4594 | E34: 1599839.8 | G34: Beverages | H34: 5697031.2 | I34: =H34/$H$45 -> 0.018760125 | J34: =SUM($H$33:H34)/SUM($H$33:$H$44) -> 0.43261339 | K34: =IF(J34<=0.8, "A", IF(J34<=0.95, "B", "C")) -> A
A35: 40918 | B35: 40918 | C35: =YEAR(B35) -> 2012 | D35: 7331 | E35: 851797.74 | G35: Cereal | H35: 5500910.2 | I35: =H35/$H$45 -> 0.018114306 | J35: =SUM($H$33:H35)/SUM($H$33:$H$44) -> 0.57657691 | K35: =IF(J35<=0.8, "A", IF(J35<=0.95, "B", "C")) -> A
A36: 40409 | B36: 40409 | C36: =YEAR(B36) -> 2010 | D36: 1270 | E36: 68668.8 | G36: Clothes | H36: 4088851.6 | I36: =H36/$H$45 -> 0.013464446 | J36: =SUM($H$33:H36)/SUM($H$33:$H$44) -> 0.68358566 | K36: =IF(J36<=0.8, "A", IF(J36<=0.95, "B", "C")) -> A
A37: 40448 | B37: 40448 | C37: =YEAR(B37) -> 2010 | D37: 7331 | E37: 1159737 | G37: Cosmetics | H37: 2953663.3 | I37: =H37/$H$45 -> 0.0097263104 | J37: =SUM($H$33:H37)/SUM($H$33:$H$44) -> 0.76088555 | K37: =IF(J37<=0.8, "A", IF(J37<=0.95, "B", "C")) -> A
A38: 42083 | B38: 42083 | C38: =YEAR(B38) -> 2015 | D38: 2103 | E38: 377464.75 | G38: Fruits | H38: 2500898.4 | I38: =H38/$H$45 -> 0.0082353713 | J38: =SUM($H$33:H38)/SUM($H$33:$H$44) -> 0.8263362 | K38: =IF(J38<=0.8, "A", IF(J38<=0.95, "B", "C")) -> B
A39: 42484 | B39: 42484 | C39: =YEAR(B39) -> 2016 | D39: 1270 | E39: 180482.96 | G39: Household | H39: 2204971.7 | I39: =H39/$H$45 -> 0.0072608951 | J39: =SUM($H$33:H39)/SUM($H$33:$H$44) -> 0.8840422 | K39: =IF(J39<=0.8, "A", IF(J39<=0.95, "B", "C")) -> B
A40: 40201 | B40: 40201 | C40: =YEAR(B40) -> 2010 | D40: 8969 | E40: 1052361.2 | G40: Meat | H40: 1777615.2 | I40: =H40/$H$45 -> 0.0058536249 | J40: =SUM($H$33:H40)/SUM($H$33:$H$44) -> 0.93056391 | K40: =IF(J40<=0.8, "A", IF(J40<=0.95, "B", "C")) -> B
...

Sheet 2017 Data
A1: Order Date | B1: Converted Date | C1: 2017 Revenue | D1: 2017 Costs | E1: 2017 Profit | F1: 2017 Units Sold | G1: Product ID | H1: Product Type | I1: % of Total Units Sold | J1: Cumulative % Units Sold | K1: % of Total Rvenue | L1: Cumulative % Revenue | M1: % of Total Profit | N1: Cumulative % Profit
A2: 41047
A3: 42245
A4: 42198
A5: 41984
A6: 42385
A7: 42930 | B7: {=IF(ISBLANK(A7:A1836),,DATEVALUE(A7:A1836))} -> 42930 | C7: =VLOOKUP(B7,events!B2:T1331,16, FALSE) -> 1168804.2 | D7: =VLOOKUP(B7,events!B2:T1331,17, FALSE) -> 878942.46 | E7: =VLOOKUP(B7,events!B2:T1331,18, FALSE) -> 289861.77 | F7: =VLOOKUP(B7,events!B2:T1331,13, FALSE) -> 1749 | G7: =VLOOKUP(A7,events!B1:L1331,11,FALSE) -> 7940 | H7: =VLOOKUP(G7,Products!$A$1:$B$13,2,FALSE) -> Household | I7: =F7/$F$1334 -> 0.0033933228 | J7: =SUM($F$7:F7)/SUM($F$7:$F$1331) -> 0.0033933228 | K7: =C7/$C$1334 -> 0.0088399654 | L7: =SUM($C$7:C7)/SUM($C$7:$C$1331) -> 0.0088399654 | M7: =E7/$E$1334 -> 0.0075859306 | N7: =SUM($E$7:E7)/SUM($E$7:$E$1331) -> 0.0075859306
A8: 41858 | B8: 41858
A9: 42072 | B9: 42072
A10: 41187 | B10: 41187
A11: 40532 | B11: 40532
A12: 42643 | B12: 42643
A13: 40640 | B13: 40640
A14: 40514 | B14: 40514
A15: 40413 | B15: 40413
A16: 40721 | B16: 40721
A17: 41392 | B17: 41392
A18: 42592 | B18: 42592
A19: 40494 | B19: 40494
... A23: 41470 | B23: 41470
A24: 42910 | B24: 42910 | C24: =VLOOKUP(B24,events!B19:T1348,16, FALSE) -> 276978.8 | D24: =VLOOKUP(B24,events!B19:T1348,17, FALSE) -> 172970.7 | E24: =VLOOKUP(B24,events!B19:T1348,18, FALSE) -> 104008.1 | F24: =VLOOKUP(B24,events!B19:T1348,13, FALSE) -> 1085 | G24: =VLOOKUP(A24,events!B18:L1348,11,FALSE) -> 7331 | H24: =VLOOKUP(G24,Products!$A$1:$B$13,2,FALSE) -> Baby Food | I24: =F24/$F$1334 -> 0.002105063 | J24: =SUM($F$7:F24)/SUM($F$7:$F$1331) -> 0.0054983858 | K24: =C24/$C$1334 -> 0.0020948615 | L24: =SUM($C$7:C24)/SUM($C$7:$C$1331) -> 0.010934827 | M24: =E24/$E$1334 -> 0.002721981 | N24: =SUM($E$7:E24)/SUM($E$7:$E$1331) -> 0.010307912
A25: 42906 | B25: 42906 | C25: =VLOOKUP(B25,events!B20:T1349,16, FALSE) -> 536455.52 | D25: =VLOOKUP(B25,events!B20:T1349,17, FALSE) -> 175938.56 | E25: =VLOOKUP(B25,events!B20:T1349,18, FALSE) -> 360516.96 | F25: =VLOOKUP(B25,events!B20:T1349,13, FALSE) -> 4909 | G25: =VLOOKUP(A25,events!B19:L1349,11,FALSE) -> 2455 | H25: =VLOOKUP(G25,Products!$A$1:$B$13,2,FALSE) -> Clothes | I25: =F25/$F$1334 -> 0.0095241976 | J25: =SUM($F$7:F25)/SUM($F$7:$F$1331) -> 0.015022583 | K25: =C25/$C$1334 -> 0.0040573503 | L25: =SUM($C$7:C25)/SUM($C$7:$C$1331) -> 0.014992177 | M25: =E25/$E$1334 -> 0.0094350373 | N25: =SUM($E$7:E25)/SUM($E$7:$E$1331) -> 0.019742949
A26: 42061 | B26: 42061
A27: 40334 | B27: 40334
A28: 41781 | B28: 41781
A29: 41009 | B29: 41009
A30: 42074 | B30: 42074
A31: 41090 | B31: 41090
A32: 40301 | B32: 40301
A33: 41238 | B33: 41238
A34: 41340 | B34: 41340
A35: 42658 | B35: 42658
A36: 42550 | B36: 42550
A37: 40918 | B37: 40918
... A58: 41786 | B58: 41786
A59: 42869 | B59: 42869 | C59: =VLOOKUP(B59,events!B54:T1383,16, FALSE) -> 276587.68 | D59: =VLOOKUP(B59,events!B54:T1383,17, FALSE) -> 90711.04 | E59: =VLOOKUP(B59,events!B54:T1383,18, FALSE) -> 185876.64 | F59: =VLOOKUP(B59,events!B54:T1383,13, FALSE) -> 2531 | G59: =VLOOKUP(A59,events!B53:L1383,11,FALSE) -> 2455 | H59: =VLOOKUP(G59,Products!$A$1:$B$13,2,FALSE) -> Clothes | I59: =F59/$F$1334 -> 0.0049105203 | J59: =SUM($F$7:F59)/SUM($F$7:$F$1331) -> 0.019933104 | K59: =C59/$C$1334 -> 0.0020919034 | L59: =SUM($C$7:C59)/SUM($C$7:$C$1331) -> 0.017084081 | M59: =E59/$E$1334 -> 0.0048645507 | N59: =SUM($E$7:E59)/SUM($E$7:$E$1331) -> 0.0246075
A60: 41556 | B60: 41556
A61: 41336 | B61: 41336
A62: 40681 | B62: 40681
A63: 40958 | B63: 40958
...

Sheet Pivot Table 52

Sheet Products
A1: Product ID | B1: Product type
A2: 7940 | B2: Household
A3: 8293 | B3: Cosmetics
A4: 7331 | B4: Baby Food
A5: 8681 | B5: Office Supplies
A6: 5988 | B6: Vegetables
A7: 8969 | B7: Snacks
A8: 1270 | B8: Beverages
A9: 2455 | B9: Clothes
A10: 8875 | B10: Meat
A11: 2103 | B11: Cereal
A12: 4594 | B12: Fruits
A13: 3127 | B13: Personal Care

Sheet ABC Analysis
A1: Product Type | B1: # of units sold | C1: Total revenue | D1: Total profit | E1: Total cost | F1: % of Total Profit | G1: Cumulative % of Profit | H1: ABC Category | I1: Rank
A2: Clothes | B2: 1342 | C2: 5714367.8 | D2: 1107843.8 | E2: 307722.24 | F2: =D2/$D$14 -> 0.30764087 | G2: =SUM($D$2:D2)/SUM($D$2:$D$13) -> 0.30764087 | H2: =IFS(G2<=0.8,"A",G2<=0.95,"B",TRUE,"C") -> A | I2: =RANK(D2,$D$2:$D$13,FALSE) -> 1
A3: Household | B3: 8586 | C3: 938278.08 | D3: 630555.84 | E3: 50931.2 | F3: =D3/$D$14 -> 0.17510118 | G3: =SUM($D$2:D3)/SUM($D$2:$D$13) -> 0.48274205 | H3: =IFS(G3<=0.8,"A",G3<=0.95,"B",TRUE,"C") -> A | I3: =RANK(D3,$D$2:$D$13,FALSE) -> 2
A4: Personal Care | B4: 46 | C4: 1447182.3 | D4: 543430.34 | E4: 599134.76 | F4: =D4/$D$14 -> 0.15090701 | G4: =SUM($D$2:D4)/SUM($D$2:$D$13) -> 0.63364906 | H4: =IFS(G4<=0.8,"A",G4<=0.95,"B",TRUE,"C") -> A | I4: =RANK(D4,$D$2:$D$13,FALSE) -> 3
A5: Baby Food | B5: 5116 | C5: 1052361.2 | D5: 453226.44 | E5: 250424.73 | F5: =D5/$D$14 -> 0.12585798 | G5: =SUM($D$2:D5)/SUM($D$2:$D$13) -> 0.75950704 | H5: =IFS(G5<=0.8,"A",G5<=0.95,"B",TRUE,"C") -> A | I5: =RANK(D5,$D$2:$D$13,FALSE) -> 4
A6: Beverages | B6: 1749 | C6: 1168804.2 | D6: 289861.77 | E6: 128050.12 | F6: =D6/$D$14 -> 0.080492694 | G6: =SUM($D$2:D6)/SUM($D$2:$D$13) -> 0.83999974 | H6: =IFS(G6<=0.8,"A",G6<=0.95,"B",TRUE,"C") -> B | I6: =RANK(D6,$D$2:$D$13,FALSE) -> 5
A7: Meat | B7: 1224 | C7: 535132.8 | D7: 212816.88 | E7: 184259.04 | F7: =D7/$D$14 -> 0.059097838 | G7: =SUM($D$2:D7)/SUM($D$2:$D$13) -> 0.89909757 | H7: =IFS(G7<=0.8,"A",G7<=0.95,"B",TRUE,"C") -> B | I7: =RANK(D7,$D$2:$D$13,FALSE) -> 6
A8: Office Supplies | B8: 4419 | C8: 361164.87 | D8: 110740.14 | E8: 878942.46 | F8: =D8/$D$14 -> 0.030751804 | G8: =SUM($D$2:D8)/SUM($D$2:$D$13) -> 0.92984938 | H8: =IFS(G8<=0.8,"A",G8<=0.95,"B",TRUE,"C") -> B | I8: =RANK(D8,$D$2:$D$13,FALSE) -> 7
A9: Snacks | B9: 1891 | C9: 288528.78 | D9: 104269.74 | E9: 4606524 | F9: =D9/$D$14 -> 0.028955016 | G9: =SUM($D$2:D9)/SUM($D$2:$D$13) -> 0.95880439 | H9: =IFS(G9<=0.8,"A",G9<=0.95,"B",TRUE,"C") -> C | I9: =RANK(D9,$D$2:$D$13,FALSE) -> 8
A10: Vegetables | B10: 4028 | C10: 191128.6 | D10: 63078.48 | E10: 322315.92 | F10: =D10/$D$14 -> 0.017516476 | G10: =SUM($D$2:D10)/SUM($D$2:$D$13) -> 0.97632087 | H10: =IFS(G10<=0.8,"A",G10<=0.95,"B",TRUE,"C") -> C | I10: =RANK(D10,$D$2:$D$13,FALSE) -> 9
A11: Cereal | B11: 865 | C11: 364934.85 | D11: 49478 | E11: 315456.85 | F11: =D11/$D$14 -> 0.013739713 | G11: =SUM($D$2:D11)/SUM($D$2:$D$13) -> 0.99006058 | H11: =IFS(G11<=0.8,"A",G11<=0.95,"B",TRUE,"C") -> C | I11: =RANK(D11,$D$2:$D$13,FALSE) -> 10
A12: Fruits | B12: 286 | C12: 44061.16 | D12: 18055.18 | E12: 26005.98 | F12: =D12/$D$14 -> 0.0050138039 | G12: =SUM($D$2:D12)/SUM($D$2:$D$13) -> 0.99507439 | H12: =IFS(G12<=0.8,"A",G12<=0.95,"B",TRUE,"C") -> C | I12: =RANK(D12,$D$2:$D$13,FALSE) -> 11
A13: Cosmetics | B13: 7360 | C13: 68668.8 | D13: 17737.6 | E13: 903751.98 | F13: =D13/$D$14 -> 0.0049256141 | G13: =SUM($D$2:D13)/SUM($D$2:$D$13) -> 1 | H13: =IFS(G13<=0.8,"A",G13<=0.95,"B",TRUE,"C") -> C | I13: =RANK(D13,$D$2:$D$13,FALSE) -> 12
D14: =SUM(D2:D13) -> 3601094.2 | E14: =SUM(E2:E13) -> 8573519.3

Sheet Shipment Turnaround Table
A1: Order Priority | B1: # of Days for Order Turnaround | C1: Classification | D1: Revenue
A2: C | B2: 2 | C2: =IFS(B2>40,"5-Slow",B2>30,"4-Medium",B2>20,"3-Fast",B2>15,"2-Very fast",TRUE,"1-Extremely fast") -> 1-Extremely fast | D2: =VLOOKUP(A2,events!F7:Q1336,12,FALSE) -> 1168804.2
A3: H | B3: 12 | C3: =IFS(B3>40,"5-Slow",B3>30,"4-Medium",B3>20,"3-Fast",B3>15,"2-Very fast",TRUE,"1-Extremely fast") -> 1-Extremely fast | D3: =VLOOKUP(A3,events!F9:Q1338,12,FALSE) -> 128076.16
A4: L | B4: 4 | C4: =IFS(B4>40,"5-Slow",B4>30,"4-Medium",B4>20,"3-Fast",B4>15,"2-Very fast",TRUE,"1-Extremely fast") -> 1-Extremely fast | D4: =VLOOKUP(A4,events!F11:Q1340,12,FALSE) -> 3698206.2
A5: L | B5: 9 | C5: =IFS(B5>40,"5-Slow",B5>30,"4-Medium",B5>20,"3-Fast",B5>15,"2-Very fast",TRUE,"1-Extremely fast") -> 1-Extremely fast | D5: =VLOOKUP(A5,events!F12:Q1341,12,FALSE) -> 4205426.8
A6: M | B6: 11 | C6: =IFS(B6>40,"5-Slow",B6>30,"4-Medium",B6>20,"3-Fast",B6>15,"2-Very fast",TRUE,"1-Extremely fast") -> 1-Extremely fast | D6: =VLOOKUP(A6,events!F13:Q1342,12,FALSE) -> 1075643
A7: H | B7: 5 | C7: =IFS(B7>40,"5-Slow",B7>30,"4-Medium",B7>20,"3-Fast",B7>15,"2-Very fast",TRUE,"1-Extremely fast") -> 1-Extremely fast | D7: =VLOOKUP(A7,events!F14:Q1343,12,FALSE) -> 288528.78
A8: L | B8: 0 | C8: =IFS(B8>40,"5-Slow",B8>30,"4-Medium",B8>20,"3-Fast",B8>15,"2-Very fast",TRUE,"1-Extremely fast") -> 1-Extremely fast | D8: =VLOOKUP(A8,events!F26:Q1355,12,FALSE) -> 758558.22
A9: H | B9: 3 | C9: =IFS(B9>40,"5-Slow",B9>30,"4-Medium",B9>20,"3-Fast",B9>15,"2-Very fast",TRUE,"1-Extremely fast") -> 1-Extremely fast | D9: =VLOOKUP(A9,events!F33:Q1362,12,FALSE) -> 278341.7
A10: C | B10: 3 | C10: =IFS(B10>40,"5-Slow",B10>30,"4-Medium",B10>20,"3-Fast",B10>15,"2-Very fast",TRUE,"1-Extremely fast") -> 1-Extremely fast | D10: =VLOOKUP(A10,events!F36:Q1365,12,FALSE) -> 68668.8
A11: H | B11: 11 | C11: =IFS(B11>40,"5-Slow",B11>30,"4-Medium",B11>20,"3-Fast",B11>15,"2-Very fast",TRUE,"1-Extremely fast") -> 1-Extremely fast | D11: =VLOOKUP(A11,events!F39:Q1368,12,FALSE) -> 180482.96
A12: C | B12: 4 | C12: =IFS(B12>40,"5-Slow",B12>30,"4-Medium",B12>20,"3-Fast",B12>15,"2-Very fast",TRUE,"1-Extremely fast") -> 1-Extremely fast | D12: =VLOOKUP(A12,events!F41:Q1370,12,FALSE) -> 167688.3
A13: C | B13: 13 | C13: =IFS(B13>40,"5-Slow",B13>30,"4-Medium",B13>20,"3-Fast",B13>15,"2-Very fast",TRUE,"1-Extremely fast") -> 1-Extremely fast | D13: =VLOOKUP(A13,events!F42:Q1371,12,FALSE) -> 1380543.8
A14: H | B14: 5 | C14: =IFS(B14>40,"5-Slow",B14>30,"4-Medium",B14>20,"3-Fast",B14>15,"2-Very fast",TRUE,"1-Extremely fast") -> 1-Extremely fast | D14: =VLOOKUP(A14,events!F49:Q1378,12,FALSE) -> 1966654.2
A15: H | B15: 7 | C15: =IFS(B15>40,"5-Slow",B15>30,"4-Medium",B15>20,"3-Fast",B15>15,"2-Very fast",TRUE,"1-Extremely fast") -> 1-Extremely fast | D15: =VLOOKUP(A15,events!F50:Q1379,12,FALSE) -> 1908484.6
A16: L | B16: 7 | C16: =IFS(B16>40,"5-Slow",B16>30,"4-Medium",B16>20,"3-Fast",B16>15,"2-Very fast",TRUE,"1-Extremely fast") -> 1-Extremely fast | D16: =VLOOKUP(A16,events!F55:Q1384,12,FALSE) -> 358794.7
A17: H | B17: 15 | C17: =IFS(B17>40,"5-Slow",B17>30,"4-Medium",B17>20,"3-Fast",B17>15,"2-Very fast",TRUE,"1-Extremely fast") -> 1-Extremely fast | D17: =VLOOKUP(A17,events!F65:Q1394,12,FALSE) -> 201926.48
A18: C | B18: 15 | C18: =IFS(B18>40,"5-Slow",B18>30,"4-Medium",B18>20,"3-Fast",B18>15,"2-Very fast",TRUE,"1-Extremely fast") -> 1-Extremely fast | D18: =VLOOKUP(A18,events!F69:Q1398,12,FALSE) -> 85966.62
A19: H | B19: 15 | C19: =IFS(B19>40,"5-Slow",B19>30,"4-Medium",B19>20,"3-Fast",B19>15,"2-Very fast",TRUE,"1-Extremely fast") -> 1-Extremely fast | D19: =VLOOKUP(A19,events!F74:Q1403,12,FALSE) -> 1533493.5
A20: L | B20: 7 | C20: =IFS(B20>40,"5-Slow",B20>30,"4-Medium",B20>20,"3-Fast",B20>15,"2-Very fast",TRUE,"1-Extremely fast") -> 1-Extremely fast | D20: =VLOOKUP(A20,events!F78:Q1407,12,FALSE) -> 4985962.5
A21: C | B21: 2 | C21: =IFS(B21>40,"5-Slow",B21>30,"4-Medium",B21>20,"3-Fast",B21>15,"2-Very fast",TRUE,"1-Extremely fast") -> 1-Extremely fast | D21: =VLOOKUP(A21,events!F80:Q1409,12,FALSE) -> 290877.07
A22: C | B22: 7 | C22: =IFS(B22>40,"5-Slow",B22>30,"4-Medium",B22>20,"3-Fast",B22>15,"2-Very fast",TRUE,"1-Extremely fast") -> 1-Extremely fast | D22: =VLOOKUP(A22,events!F89:Q1418,12,FALSE) -> 594046.08
A23: H | B23: 5 | C23: =IFS(B23>40,"5-Slow",B23>30,"4-Medium",B23>20,"3-Fast",B23>15,"2-Very fast",TRUE,"1-Extremely fast") -> 1-Extremely fast | D23: =VLOOKUP(A23,events!F91:Q1420,12,FALSE) -> 4166163.8
A24: M | B24: 11 | C24: =IFS(B24>40,"5-Slow",B24>30,"4-Medium",B24>20,"3-Fast",B24>15,"2-Very fast",TRUE,"1-Extremely fast") -> 1-Extremely fast | D24: =VLOOKUP(A24,events!F93:Q1422,12,FALSE) -> 98484.65
A25: H | B25: 3 | C25: =IFS(B25>40,"5-Slow",B25>30,"4-Medium",B25>20,"3-Fast",B25>15,"2-Very fast",TRUE,"1-Extremely fast") -> 1-Extremely fast | D25: =VLOOKUP(A25,events!F98:Q1427,12,FALSE) -> 4344873.1
A26: M | B26: 9 | C26: =IFS(B26>40,"5-Slow",B26>30,"4-Medium",B26>20,"3-Fast",B26>15,"2-Very fast",TRUE,"1-Extremely fast") -> 1-Extremely fast | D26: =VLOOKUP(A26,events!F101:Q1430,12,FALSE) -> 1048682.3
A27: H | B27: 10 | C27: =IFS(B27>40,"5-Slow",B27>30,"4-Medium",B27>20,"3-Fast",B27>15,"2-Very fast",TRUE,"1-Extremely fast") -> 1-Extremely fast | D27: =VLOOKUP(A27,events!F114:Q1443,12,FALSE) -> 2010305.9
A28: M | B28: 7 | C28: =IFS(B28>40,"5-Slow",B28>30,"4-Medium",B28>20,"3-Fast",B28>15,"2-Very fast",TRUE,"1-Extremely fast") -> 1-Extremely fast | D28: =VLOOKUP(A28,events!F115:Q1444,12,FALSE) -> 268500.96
A29: M | B29: 8 | C29: =IFS(B29>40,"5-Slow",B29>30,"4-Medium",B29>20,"3-Fast",B29>15,"2-Very fast",TRUE,"1-Extremely fast") -> 1-Extremely fast | D29: =VLOOKUP(A29,events!F118:Q1447,12,FALSE) -> 164195.57
A30: M | B30: 9 | C30: =IFS(B30>40,"5-Slow",B30>30,"4-Medium",B30>20,"3-Fast",B30>15,"2-Very fast",TRUE,"1-Extremely fast") -> 1-Extremely fast | D30: =VLOOKUP(A30,events!F121:Q1450,12,FALSE) -> 243798.1
A31: C | B31: 7 | C31: =IFS(B31>40,"5-Slow",B31>30,"4-Medium",B31>20,"3-Fast",B31>15,"2-Very fast",TRUE,"1-Extremely fast") -> 1-Extremely fast | D31: =VLOOKUP(A31,events!F123:Q1452,12,FALSE) -> 1038364.4
A32: M | B32: 14 | C32: =IFS(B32>40,"5-Slow",B32>30,"4-Medium",B32>20,"3-Fast",B32>15,"2-Very fast",TRUE,"1-Extremely fast") -> 1-Extremely fast | D32: =VLOOKUP(A32,events!F124:Q1453,12,FALSE) -> 772764.96
A33: L | B33: 15 | C33: =IFS(B33>40,"5-Slow",B33>30,"4-Medium",B33>20,"3-Fast",B33>15,"2-Very fast",TRUE,"1-Extremely fast") -> 1-Extremely fast | D33: =VLOOKUP(A33,events!F125:Q1454,12,FALSE) -> 752858.4
A34: H | B34: 11 | C34: =IFS(B34>40,"5-Slow",B34>30,"4-Medium",B34>20,"3-Fast",B34>15,"2-Very fast",TRUE,"1-Extremely fast") -> 1-Extremely fast | D34: =VLOOKUP(A34,events!F126:Q1455,12,FALSE) -> 152504.3
A35: L | B35: 11 | C35: =IFS(B35>40,"5-Slow",B35>30,"4-Medium",B35>20,"3-Fast",B35>15,"2-Very fast",TRUE,"1-Extremely fast") -> 1-Extremely fast | D35: =VLOOKUP(A35,events!F129:Q1458,12,FALSE) -> 1245729.2
A36: C | B36: 4 | C36: =IFS(B36>40,"5-Slow",B36>30,"4-Medium",B36>20,"3-Fast",B36>15,"2-Very fast",TRUE,"1-Extremely fast") -> 1-Extremely fast | D36: =VLOOKUP(A36,events!F134:Q1463,12,FALSE) -> 187953.2
A37: C | B37: 13 | C37: =IFS(B37>40,"5-Slow",B37>30,"4-Medium",B37>20,"3-Fast",B37>15,"2-Very fast",TRUE,"1-Extremely fast") -> 1-Extremely fast | D37: =VLOOKUP(A37,events!F138:Q1467,12,FALSE) -> 50587.26
A38: L | B38: 2 | C38: =IFS(B38>40,"5-Slow",B38>30,"4-Medium",B38>20,"3-Fast",B38>15,"2-Very fast",TRUE,"1-Extremely fast") -> 1-Extremely fast | D38: =VLOOKUP(A38,events!F140:Q1469,12,FALSE) -> 1710395.5
A39: H | B39: 14 | C39: =IFS(B39>40,"5-Slow",B39>30,"4-Medium",B39>20,"3-Fast",B39>15,"2-Very fast",TRUE,"1-Extremely fast") -> 1-Extremely fast | D39: =VLOOKUP(A39,events!F141:Q1470,12,FALSE) -> 137984.6
A40: L | B40: 1 | C40: =IFS(B40>40,"5-Slow",B40>30,"4-Medium",B40>20,"3-Fast",B40>15,"2-Very fast",TRUE,"1-Extremely fast") -> 1-Extremely fast | D40: =VLOOKUP(A40,events!F144:Q1473,12,FALSE) -> 778947.84
...

Sheet 10.Product Sales by Week
A1: Product Units Sold | B1: Product Type
A2: Day of week | B2: Baby Food | C2: Beverages | D2: Cereal | E2: Clothes | F2: Cosmetics | G2: Fruits | H2: Household | I2: Meat | J2: Office Supplies | K2: Personal Care | L2: Snacks | M2: Vegetables
A3: 1 - Mon | B3: 25829 | C3: 67094 | D3: 18751 | E3: 30254 | F3: 22347 | G3: 52692 | H3: 71735 | I3: 59763 | J3: 47566 | K3: 6040 | L3: 77832 | M3: 36257
A4: 2 - Tue | B4: 35907 | C4: 39619 | D4: 50181 | E4: 47791 | F4: 61258 | G4: 23022 | H4: 6126 | I4: 43948 | J4: 33431 | K4: 39096 | L4: 35443 | M4: 34074
A5: 3 - Wed | B5: 30579 | C5: 40767 | D5: 34564 | E5: 18557 | F5: 17729 | G5: 23285 | H5: 63860 | I5: 27467 | J5: 36474 | K5: 36656 | L5: 16796 | M5: 22193
A6: 4 - Thu | B6: 20012 | C6: 40585 | D6: 27447 | E6: 48047 | F6: 35422 | G6: 34334 | H6: 19202 | I6: 30745 | J6: 21478 | K6: 34486 | L6: 18823 | M6: 51576
A7: 5 - Fri | B7: 16257 | C7: 26965 | D7: 35369 | E7: 35480 | F7: 69633 | G7: 16825 | H7: 31108 | I7: 18376 | J7: 33407 | K7: 40408 | L7: 43126 | M7: 35440
A8: 6 - Sat | B8: 40455 | C8: 27483 | D8: 39770 | E8: 58144 | F8: 33401 | G8: 45995 | H8: 30021 | I8: 33717 | J8: 16201 | K8: 41548 | L8: 30430 | M8: 27092
A9: 7 - Sun | B9: 37887 | C9: 58217 | D9: 46204 | E9: 46665 | F9: 15802 | G9: 61349 | H9: 18481 | I9: 25241 | J9: 60825 | K9: 48228 | L9: 29733 | M9: 65836

Sheet 9ca.Regions Revenue Year-on-Yea
A1: Order Date | B1: Year | C1: Country Region | D1: Total Revenue
A2: 41047 | B2: =IFERROR(__xludf.DUMMYFUNCTION("YEAR(TO_DATE(A2))"),2012.0) -> 2012 | C2: Europe | D2: 1447182.3
A3: 42245 | B3: =IFERROR(__xludf.DUMMYFUNCTION("YEAR(TO_DATE(A3))"),2015.0) -> 2015 | C3: Europe | D3: 535132.8
A4: 42198 | B4: =IFERROR(__xludf.DUMMYFUNCTION("YEAR(TO_DATE(A4))"),2015.0) -> 2015 | C4: Europe | D4: 5714367.8
A5: 41984 | B5: =IFERROR(__xludf.DUMMYFUNCTION("YEAR(TO_DATE(A5))"),2014.0) -> 2014 | C5: Europe | D5: 191128.6
A6: 42385 | B6: =IFERROR(__xludf.DUMMYFUNCTION("YEAR(TO_DATE(A6))"),2016.0) -> 2016 | C6: Europe | D6: 938278.08
A7: 42930 | B7: =IFERROR(__xludf.DUMMYFUNCTION("YEAR(TO_DATE(A7))"),2017.0) -> 2017 | C7: Europe | D7: 1168804.2
A8: 41858 | B8: =IFERROR(__xludf.DUMMYFUNCTION("YEAR(TO_DATE(A8))"),2014.0) -> 2014 | C8: Europe | D8: 44061.16
A9: 42072 | B9: =IFERROR(__xludf.DUMMYFUNCTION("YEAR(TO_DATE(A9))"),2015.0) -> 2015 | C9: Europe | D9: 128076.16
A10: 41187 | B10: =IFERROR(__xludf.DUMMYFUNCTION("YEAR(TO_DATE(A10))"),2012.0) -> 2012 | C10: Europe | D10: 818058.6
A11: 40532 | B11: =IFERROR(__xludf.DUMMYFUNCTION("YEAR(TO_DATE(A11))"),2010.0) -> 2010 | C11: Europe | D11: 3698206.2
A12: 42643 | B12: =IFERROR(__xludf.DUMMYFUNCTION("YEAR(TO_DATE(A12))"),2016.0) -> 2016 | C12: Europe | D12: 4205426.8
A13: 40640 | B13: =IFERROR(__xludf.DUMMYFUNCTION("YEAR(TO_DATE(A13))"),2011.0) -> 2011 | C13: Europe | D13: 1075643
A14: 40514 | B14: =IFERROR(__xludf.DUMMYFUNCTION("YEAR(TO_DATE(A14))"),2010.0) -> 2010 | C14: Europe | D14: 288528.78
A15: 40413 | B15: =IFERROR(__xludf.DUMMYFUNCTION("YEAR(TO_DATE(A15))"),2010.0) -> 2010 | C15: Europe | D15: 4179632
A16: 40721 | B16: =IFERROR(__xludf.DUMMYFUNCTION("YEAR(TO_DATE(A16))"),2011.0) -> 2011 | C16: Europe | D16: 2189934.8
A17: 41392 | B17: =IFERROR(__xludf.DUMMYFUNCTION("YEAR(TO_DATE(A17))"),2013.0) -> 2013 | C17: Europe | D17: 107426.8
A18: 42592 | B18: =IFERROR(__xludf.DUMMYFUNCTION("YEAR(TO_DATE(A18))"),2016.0) -> 2016 | C18: Europe | D18: 873923.82
A19: 40494 | B19: =IFERROR(__xludf.DUMMYFUNCTION("YEAR(TO_DATE(A19))"),2010.0) -> 2010 | C19: Europe | D19: 364934.85
A20: 41191 | B20: =IFERROR(__xludf.DUMMYFUNCTION("YEAR(TO_DATE(A20))"),2012.0) -> 2012 | C20: Europe | D20: 53333.8
A21: 41305 | B21: =IFERROR(__xludf.DUMMYFUNCTION("YEAR(TO_DATE(A21))"),2013.0) -> 2013 | C21: Europe | D21: 536644.08
A22: 40999 | B22: =IFERROR(__xludf.DUMMYFUNCTION("YEAR(TO_DATE(A22))"),2012.0) -> 2012 | C22: Europe | D22: 3666129.2
A23: 41470 | B23: =IFERROR(__xludf.DUMMYFUNCTION("YEAR(TO_DATE(A23))"),2013.0) -> 2013 | C23: Europe | D23: 11742.88
A24: 42910 | B24: =IFERROR(__xludf.DUMMYFUNCTION("YEAR(TO_DATE(A24))"),2017.0) -> 2017 | C24: Europe | D24: 276978.8
A25: 42906 | B25: =IFERROR(__xludf.DUMMYFUNCTION("YEAR(TO_DATE(A25))"),2017.0) -> 2017 | C25: Europe | D25: 536455.52
A26: 42061 | B26: =IFERROR(__xludf.DUMMYFUNCTION("YEAR(TO_DATE(A26))"),2015.0) -> 2015 | C26: Europe | D26: 758558.22
A27: 40334 | B27: =IFERROR(__xludf.DUMMYFUNCTION("YEAR(TO_DATE(A27))"),2010.0) -> 2010 | C27: Europe | D27: 361164.87
A28: 41781 | B28: =IFERROR(__xludf.DUMMYFUNCTION("YEAR(TO_DATE(A28))"),2014.0) -> 2014 | C28: Europe | D28: 2156507.3
A29: 41009 | B29: =IFERROR(__xludf.DUMMYFUNCTION("YEAR(TO_DATE(A29))"),2012.0) -> 2012 | C29: Europe | D29: 4275816
A30: 42074 | B30: =IFERROR(__xludf.DUMMYFUNCTION("YEAR(TO_DATE(A30))"),2015.0) -> 2015 | C30: Europe | D30: 73310.25
A31: 41090 | B31: =IFERROR(__xludf.DUMMYFUNCTION("YEAR(TO_DATE(A31))"),2012.0) -> 2012 | C31: Europe | D31: 3006187.2
A32: 40301 | B32: =IFERROR(__xludf.DUMMYFUNCTION("YEAR(TO_DATE(A32))"),2010.0) -> 2010 | C32: Europe | D32: 556306.68
A33: 41238 | B33: =IFERROR(__xludf.DUMMYFUNCTION("YEAR(TO_DATE(A33))"),2012.0) -> 2012 | C33: Europe | D33: 278341.7
A34: 41340 | B34: =IFERROR(__xludf.DUMMYFUNCTION("YEAR(TO_DATE(A34))"),2013.0) -> 2013 | C34: Europe | D34: 1599839.8
A35: 42658 | B35: =IFERROR(__xludf.DUMMYFUNCTION("YEAR(TO_DATE(A35))"),2016.0) -> 2016 | C35: Europe | D35: 851797.74
A36: 42550 | B36: =IFERROR(__xludf.DUMMYFUNCTION("YEAR(TO_DATE(A36))"),2016.0) -> 2016 | C36: Europe | D36: 68668.8
A37: 40918 | B37: =IFERROR(__xludf.DUMMYFUNCTION("YEAR(TO_DATE(A37))"),2012.0) -> 2012 | C37: Europe | D37: 1159737
A38: 40409 | B38: =IFERROR(__xludf.DUMMYFUNCTION("YEAR(TO_DATE(A38))"),2010.0) -> 2010 | C38: Europe | D38: 377464.75
A39: 40448 | B39: =IFERROR(__xludf.DUMMYFUNCTION("YEAR(TO_DATE(A39))"),2010.0) -> 2010 | C39: Europe | D39: 180482.96
A40: 42083 | B40: =IFERROR(__xludf.DUMMYFUNCTION("YEAR(TO_DATE(A40))"),2015.0) -> 2015 | C40: Europe | D40: 1052361.2
...

Sheet 9ca. Regions Revenue Year-on-Ye

Sheet 9cb.Regions Revenue by Month
A1: Order Date | B1: Month | D1: Country Region | E1: Ordered Month | F1: Total Revenue
A2: 40931 | B2: =TEXT(A2,"MMMM") -> January | C2: =MONTH(A2) -> 1 | D2: Asia | E2: =C2 & " " & B2 -> 1 January | F2: 201926.48
A3: 42016 | B3: =TEXT(A3,"MMMM") -> January | C3: =MONTH(A3) -> 1 | D3: Europe | E3: =C3 & " " & B3 -> 1 January | F3: 763662.9
A4: 41652 | B4: =TEXT(A4,"MMMM") -> January | C4: =MONTH(A4) -> 1 | D4: Europe | E4: =C4 & " " & B4 -> 1 January | F4: 541810.24
A5: 40196 | B5: =TEXT(A5,"MMMM") -> January | C5: =MONTH(A5) -> 1 | D5: Asia | E5: =C5 & " " & B5 -> 1 January | F5: 165676.72
A6: 40931 | B6: =TEXT(A6,"MMMM") -> January | C6: =MONTH(A6) -> 1 | D6: Europe | E6: =C6 & " " & B6 -> 1 January | F6: 6111997.4
A7: 41645 | B7: =TEXT(A7,"MMMM") -> January | C7: =MONTH(A7) -> 1 | D7: Europe | E7: =C7 & " " & B7 -> 1 January | F7: 1118321.5
A8: 41666 | B8: =TEXT(A8,"MMMM") -> January | C8: =MONTH(A8) -> 1 | D8: Europe | E8: =C8 & " " & B8 -> 1 January | F8: 64730.16
A9: 42016 | B9: =TEXT(A9,"MMMM") -> January | C9: =MONTH(A9) -> 1 | D9: Europe | E9: =C9 & " " & B9 -> 1 January | F9: 3872280.4
A10: 40938 | B10: =TEXT(A10,"MMMM") -> January | C10: =MONTH(A10) -> 1 | D10: Europe | E10: =C10 & " " & B10 -> 1 January | F10: 5159536.8
A11: 40189 | B11: =TEXT(A11,"MMMM") -> January | C11: =MONTH(A11) -> 1 | D11: Europe | E11: =C11 & " " & B11 -> 1 January | F11: 1592436.6
A12: 40189 | B12: =TEXT(A12,"MMMM") -> January | C12: =MONTH(A12) -> 1 | D12: Europe | E12: =C12 & " " & B12 -> 1 January | F12: 1299523.9
A13: 40910 | B13: =TEXT(A13,"MMMM") -> January | C13: =MONTH(A13) -> 1 | D13: Europe | E13: =C13 & " " & B13 -> 1 January | F13: 243038.9
... A1331: 40447 | B1331: =TEXT(A1331,"MMMM") -> September | C1331: =MONTH(A1331) -> 9 | D1331: Unknown Country | E1331: =C1331 & " " & B1331 -> 9 September | F1331: 680720.4

Sheet 9cb.Regions Revenue by Month Pi

Sheet 9aa.Product Sales by Year
A1: Order Date | B1: Year | C1: Product Name | D1: Total Revenue
A2: 41047 | B2: =IFERROR(__xludf.DUMMYFUNCTION("YEAR(TO_DATE(A2))"),2012.0) -> 2012 | C2: Baby Food | D2: 1447182.3
A3: 42245 | B3: =IFERROR(__xludf.DUMMYFUNCTION("YEAR(TO_DATE(A3))"),2015.0) -> 2015 | C3: Cosmetics | D3: 535132.8
A4: 42198 | B4: =IFERROR(__xludf.DUMMYFUNCTION("YEAR(TO_DATE(A4))"),2015.0) -> 2015 | C4: Office Supplies | D4: 5714367.8
A5: 41984 | B5: =IFERROR(__xludf.DUMMYFUNCTION("YEAR(TO_DATE(A5))"),2014.0) -> 2014 | C5: Beverages | D5: 191128.6
A6: 42385 | B6: =IFERROR(__xludf.DUMMYFUNCTION("YEAR(TO_DATE(A6))"),2016.0) -> 2016 | C6: Clothes | D6: 938278.08
A7: 42930 | B7: =IFERROR(__xludf.DUMMYFUNCTION("YEAR(TO_DATE(A7))"),2017.0) -> 2017 | C7: Household | D7: 1168804.2
A8: 41858 | B8: =IFERROR(__xludf.DUMMYFUNCTION("YEAR(TO_DATE(A8))"),2014.0) -> 2014 | C8: Vegetables | D8: 44061.16
A9: 42072 | B9: =IFERROR(__xludf.DUMMYFUNCTION("YEAR(TO_DATE(A9))"),2015.0) -> 2015 | C9: Clothes | D9: 128076.16
A10: 41187 | B10: =IFERROR(__xludf.DUMMYFUNCTION("YEAR(TO_DATE(A10))"),2012.0) -> 2012 | C10: Vegetables | D10: 818058.6
A11: 40532 | B11: =IFERROR(__xludf.DUMMYFUNCTION("YEAR(TO_DATE(A11))"),2010.0) -> 2010 | C11: Household | D11: 3698206.2
A12: 42643 | B12: =IFERROR(__xludf.DUMMYFUNCTION("YEAR(TO_DATE(A12))"),2016.0) -> 2016 | C12: Cosmetics | D12: 4205426.8
A13: 40640 | B13: =IFERROR(__xludf.DUMMYFUNCTION("YEAR(TO_DATE(A13))"),2011.0) -> 2011 | C13: Clothes | D13: 1075643
A14: 40514 | B14: =IFERROR(__xludf.DUMMYFUNCTION("YEAR(TO_DATE(A14))"),2010.0) -> 2010 | C14: Snacks | D14: 288528.78
A15: 40413 | B15: =IFERROR(__xludf.DUMMYFUNCTION("YEAR(TO_DATE(A15))"),2010.0) -> 2010 | C15: Cosmetics | D15: 4179632
A16: 40721 | B16: =IFERROR(__xludf.DUMMYFUNCTION("YEAR(TO_DATE(A16))"),2011.0) -> 2011 | C16: Cosmetics | D16: 2189934.8
A17: 41392 | B17: =IFERROR(__xludf.DUMMYFUNCTION("YEAR(TO_DATE(A17))"),2013.0) -> 2013 | C17: Beverages | D17: 107426.8
A18: 42592 | B18: =IFERROR(__xludf.DUMMYFUNCTION("YEAR(TO_DATE(A18))"),2016.0) -> 2016 | C18: Office Supplies | D18: 873923.82
A19: 40494 | B19: =IFERROR(__xludf.DUMMYFUNCTION("YEAR(TO_DATE(A19))"),2010.0) -> 2010 | C19: Meat | D19: 364934.85
A20: 41191 | B20: =IFERROR(__xludf.DUMMYFUNCTION("YEAR(TO_DATE(A20))"),2012.0) -> 2012 | C20: Beverages | D20: 53333.8
A21: 41305 | B21: =IFERROR(__xludf.DUMMYFUNCTION("YEAR(TO_DATE(A21))"),2013.0) -> 2013 | C21: Meat | D21: 536644.08
A22: 40999 | B22: =IFERROR(__xludf.DUMMYFUNCTION("YEAR(TO_DATE(A22))"),2012.0) -> 2012 | C22: Household | D22: 3666129.2
A23: 41470 | B23: =IFERROR(__xludf.DUMMYFUNCTION("YEAR(TO_DATE(A23))"),2013.0) -> 2013 | C23: Baby Food | D23: 11742.88
A24: 42910 | B24: =IFERROR(__xludf.DUMMYFUNCTION("YEAR(TO_DATE(A24))"),2017.0) -> 2017 | C24: Baby Food | D24: 276978.8
A25: 42906 | B25: =IFERROR(__xludf.DUMMYFUNCTION("YEAR(TO_DATE(A25))"),2017.0) -> 2017 | C25: Clothes | D25: 536455.52
A26: 42061 | B26: =IFERROR(__xludf.DUMMYFUNCTION("YEAR(TO_DATE(A26))"),2015.0) -> 2015 | C26: Meat | D26: 758558.22
A27: 40334 | B27: =IFERROR(__xludf.DUMMYFUNCTION("YEAR(TO_DATE(A27))"),2010.0) -> 2010 | C27: Personal Care | D27: 361164.87
A28: 41781 | B28: =IFERROR(__xludf.DUMMYFUNCTION("YEAR(TO_DATE(A28))"),2014.0) -> 2014 | C28: Household | D28: 2156507.3
A29: 41009 | B29: =IFERROR(__xludf.DUMMYFUNCTION("YEAR(TO_DATE(A29))"),2012.0) -> 2012 | C29: Cosmetics | D29: 4275816
A30: 42074 | B30: =IFERROR(__xludf.DUMMYFUNCTION("YEAR(TO_DATE(A30))"),2015.0) -> 2015 | C30: Beverages | D30: 73310.25
A31: 41090 | B31: =IFERROR(__xludf.DUMMYFUNCTION("YEAR(TO_DATE(A31))"),2012.0) -> 2012 | C31: Cosmetics | D31: 3006187.2
A32: 40301 | B32: =IFERROR(__xludf.DUMMYFUNCTION("YEAR(TO_DATE(A32))"),2010.0) -> 2010 | C32: Snacks | D32: 556306.68
A33: 41238 | B33: =IFERROR(__xludf.DUMMYFUNCTION("YEAR(TO_DATE(A33))"),2012.0) -> 2012 | C33: Beverages | D33: 278341.7
A34: 41340 | B34: =IFERROR(__xludf.DUMMYFUNCTION("YEAR(TO_DATE(A34))"),2013.0) -> 2013 | C34: Baby Food | D34: 1599839.8
